<?xml version="1.0" ?>

<sdf version="1.5">
  <model name="teapot">
    <link name="chassis">
      <pose>0 0 0.30000000000000004  0 0 0</pose>
      <inertial>
        <pose>0.1 0 0  0 0 0</pose>
        <mass>10</mass>
        <inertia>
          <ixx>0.2833333333333333</ixx>
          <iyy>0.9083333333333334</iyy>
          <izz>1.0416666666666667</izz>
          <ixy>0</ixy>
          <ixz>0</ixz>
          <iyz>0</iyz>
        </inertia>
      </inertial>
      <collision name="collision">
        <geometry>
          <box>
            <size>1.0 0.5 0.3</size>
          </box>
        </geometry>
      </collision>
      <visual name="visual">
        <geometry>
          <box>
            <size>1.0 0.5 0.3</size>
          </box>
        </geometry>
        <material>
          <script>
            <uri>file://media/materials/scripts/gazebo.material</uri>
            <name>Gazebo/Grey</name>
          </script>
        </material>
      </visual>
    </link>
    
    <link name="wheel_fl">
      <pose>
        0.5 0.348 0.1
        -1.5707963267948966 -0.08726646259971647 0
      </pose>
      <inertial>
        <mass>0.5</mass>
        <inertia>
          <ixx>0.001516666666666667</ixx>
          <iyy>0.001516666666666667</iyy>
          <izz>0.0025000000000000005</izz>
          <ixy>0</ixy>
          <ixz>0</ixz>
          <iyz>0</iyz>
        </inertia>
      </inertial>
      <collision name="collision">
        <geometry>
          <cylinder>
            <radius>0.1</radius>
            <length>0.08</length>
          </cylinder>
        </geometry>
      </collision>
      <visual name="visual">
        <geometry>
          <cylinder>
            <radius>0.1</radius>
            <length>0.08</length>
          </cylinder>
        </geometry>
        <material>
          <script>
            <uri>file://media/materials/scripts/gazebo.material</uri>
            <name>Gazebo/Black</name>
          </script>
        </material>
      </visual>
    </link>
    
    <joint name="wheel_fl_steer" type="universal">
      <parent>chassis</parent>
      <child>wheel_fl</child>
      <axis>
        <xyz>0 -1 0</xyz>
        <limit>
          <lower>-1.3089969389957472</lower>
          <upper>1.3089969389957472</upper>
        </limit>
      </axis>
      <axis2>
        <xyz>0 0 1</xyz>
      </axis2>
    </joint>
    
    <link name="wheel_fr">
      <pose>
        0.5 -0.348 0.1
        -1.5707963267948966 -0.08726646259971647 0
      </pose>
      <inertial>
        <mass>0.5</mass>
        <inertia>
          <ixx>0.001516666666666667</ixx>
          <iyy>0.001516666666666667</iyy>
          <izz>0.0025000000000000005</izz>
          <ixy>0</ixy>
          <ixz>0</ixz>
          <iyz>0</iyz>
        </inertia>
      </inertial>
      <collision name="collision">
        <geometry>
          <cylinder>
            <radius>0.1</radius>
            <length>0.08</length>
          </cylinder>
        </geometry>
      </collision>
      <visual name="visual">
        <geometry>
          <cylinder>
            <radius>0.1</radius>
            <length>0.08</length>
          </cylinder>
        </geometry>
        <material>
          <script>
            <uri>file://media/materials/scripts/gazebo.material</uri>
            <name>Gazebo/Black</name>
          </script>
        </material>
      </visual>
    </link>
    
    <joint name="wheel_fr_steer" type="universal">
      <parent>chassis</parent>
      <child>wheel_fr</child>
      <axis>
        <xyz>0 -1 0</xyz>
        <limit>
          <lower>-1.3089969389957472</lower>
          <upper>1.3089969389957472</upper>
        </limit>
      </axis>
      <axis2>
        <xyz>0 0 1</xyz>
      </axis2>
    </joint>
    
    
    <link name="wheel_rl">
      <pose>-0.5 0.348 0.1  -1.5707963267948966 0 0</pose>
      <inertial>
        <mass>0.5</mass>
        <inertia>
          <ixx>0.001516666666666667</ixx>
          <iyy>0.001516666666666667</iyy>
          <izz>0.0025000000000000005</izz>
          <ixy>0</ixy>
          <ixz>0</ixz>
          <iyz>0</iyz>
        </inertia>
      </inertial>
      <collision name="collision">
        <geometry>
          <cylinder>
            <radius>0.1</radius>
            <length>0.08</length>
          </cylinder>
        </geometry>
      </collision>
      <visual name="visual">
        <geometry>
          <cylinder>
            <radius>0.1</radius>
            <length>0.08</length>
          </cylinder>
        </geometry>
        <material>
          <script>
            <uri>file://media/materials/scripts/gazebo.material</uri>
            <name>Gazebo/Black</name>
          </script>
        </material>
      </visual>
    </link>
    <joint name="wheel_rl_drive" type="revolute">
      <parent>chassis</parent>
      <child>wheel_rl</child>
      <axis>
        <xyz>0 0 1</xyz>
      </axis>
    </joint>
    
    <link name="wheel_rr">
      <pose>-0.5 -0.348 0.1  -1.5707963267948966 0 0</pose>
      <inertial>
        <mass>0.5</mass>
        <inertia>
          <ixx>0.001516666666666667</ixx>
          <iyy>0.001516666666666667</iyy>
          <izz>0.0025000000000000005</izz>
          <ixy>0</ixy>
          <ixz>0</ixz>
          <iyz>0</iyz>
        </inertia>
      </inertial>
      <collision name="collision">
        <geometry>
          <cylinder>
            <radius>0.1</radius>
            <length>0.08</length>
          </cylinder>
        </geometry>
      </collision>
      <visual name="visual">
        <geometry>
          <cylinder>
            <radius>0.1</radius>
            <length>0.08</length>
          </cylinder>
        </geometry>
        <material>
          <script>
            <uri>file://media/materials/scripts/gazebo.material</uri>
            <name>Gazebo/Black</name>
          </script>
        </material>
      </visual>
    </link>
    <joint name="wheel_rr_drive" type="revolute">
      <parent>chassis</parent>
      <child>wheel_rr</child>
      <axis>
        <xyz>0 0 1</xyz>
      </axis>
    </joint>
    

    <include>
      <uri>model://rplidar_a2</uri>
      <pose>0.0 0 0.5 0 0 0</pose>
    </include>
    <joint name="lidar_joint" type="fixed">
      <child>rplidar_a2::link</child>
      <parent>chassis</parent>
    </joint>
  </model>
</sdf>
